[META]
version=2.0
spawnOnBlockType=12
spawnSunlight=False
spawnDarkness=True
spawnWater=True
spawnLava=False
underFill=False
randomRotation=True
dig=False
tree=False
branch=False
needsFoundation=False
rarity=99
collisionPercentage=80
spawnElevationMin=0
spawnElevationMax=64
groupId=ships
groupFrequencyMin=1
groupFrequencyMax=5
groupSeperationMin=0
groupSeperationMax=5
branchLimit=6
spawnInBiome=All
[DATA]
2,1,0:17.0
-2,-1,0:17.0
2,-1,0:17.0
2,0,0:17.0
-2,0,0:17.0
-2,1,0:17.0
-2,-2,0:17.0
2,-2,0:17.0
2,-3,0:17.0
-1,-3,0:17.0
-2,-3,0:17.0
-2,2,0:17.0
2,2,0:17.0
2,3,0:17.0
1,3,0:17.0
-1,3,0:17.0
-2,3,0:17.0
-1,4,0:17.0
0,4,0:17.0
1,4,0:17.0
-1,-4,0:17.0
0,-4,0:17.0
1,-4,0:17.0
1,-3,0:17.0
0,1,0:5
0,-1,0:53.2
0,0,0:5
0,0,-1:17.0
-1,0,-1:17.0
-1,-2,-1:17.0
-1,-1,-1:17.0
0,-2,-1:17.0
0,-1,-1:17.0
1,-1,-1:17.0
1,-2,-1:17.0
1,0,-1:17.0
1,1,-1:17.0
1,2,-1:17.0
0,2,-1:17.0
-1,2,-1:17.0
-1,1,-1:17.0
0,1,-1:17.0
0,3,-1:17.0
0,-3,-1:17.0
-2,-4,1:17.0
-1,-5,1:17.0
0,-5,1:17.0
-2,-5,1:17.0
-3,-3,1:17.0
-3,-4,1:17.0
-3,-2,1:17.0
-3,-1,1:17.0
-3,0,1:17.0
-3,1,1:17.0
-3,2,1:17.0
-3,3,1:17.0
-3,4,1:17.0
-2,4,1:17.0
-2,5,1:17.0
-1,5,1:17.0
0,5,1:17.0
1,5,1:17.0
2,5,1:17.0
2,4,1:17.0
3,4,1:17.0
3,3,1:17.0
3,1,1:17.0
3,0,1:17.0
3,-1,1:17.0
3,-2,1:17.0
3,-3,1:17.0
3,2,1:17.0
3,-4,1:17.0
2,-4,1:17.0
2,-5,1:17.0
1,-5,1:17.0
0,0,1:53.2
0,1,1:5
-2,-4,2:17.0
-2,-5,2:17.0
-1,-5,2:17.0
0,-5,2:17.0
1,-5,2:17.0
2,-5,2:17.0
2,-4,2:17.0
3,-2,2:17.0
3,-3,2:17.0
3,-4,2:17.0
3,-1,2:17.0
3,0,2:17.0
3,1,2:17.0
3,2,2:17.0
3,3,2:17.0
3,4,2:17.0
2,4,2:17.0
2,5,2:17.0
1,5,2:17.0
0,5,2:17.0
-1,5,2:17.0
-2,5,2:17.0
-2,4,2:17.0
-3,4,2:17.0
-3,3,2:17.0
-3,2,2:17.0
-3,1,2:17.0
-3,0,2:17.0
-3,-1,2:17.0
-3,-2,2:17.0
-3,-3,2:17.0
-3,-4,2:17.0
-2,-3,2:5
-2,-2,2:5
-2,-1,2:5
-2,0,2:5
-2,1,2:5
-2,2,2:5
-2,3,2:5
-1,3,2:5
0,3,2:5
0,4,2:5
-1,4,2:5
1,4,2:5
1,3,2:5
2,3,2:5
2,2,2:5
2,1,2:5
2,0,2:5
2,-1,2:5
2,-2,2:5
2,-3,2:5
1,-4,2:5
0,-4,2:5
-1,-4,2:5
-1,-3,2:5
-1,-2,2:5
-1,-1,2:5
-1,0,2:5
-1,1,2:5
-1,2,2:5
0,2,2:5
1,2,2:5
1,1,2:5
1,0,2:5
1,-1,2:5
1,-2,2:5
1,-3,2:5
0,-3,2:5
0,-2,2:5
0,1,2:53.2
-3,-5,3:17.0
-2,-6,3:17.0
-1,-6,3:17.0
0,-6,3:17.0
1,-6,3:17.0
2,-6,3:17.0
3,-6,3:17.0
3,-5,3:17.0
4,-5,3:17.0
4,-4,3:17.0
-3,-6,3:17.0
-4,-4,3:17.0
-4,-5,3:17.0
-4,-3,3:17.0
-4,-2,3:17.0
-4,-1,3:17.0
-4,0,3:17.0
-4,1,3:17.0
-4,2,3:17.0
-4,3,3:17.0
-4,4,3:17.0
-4,5,3:17.0
-3,5,3:17.0
-3,6,3:17.0
-2,6,3:17.0
-1,6,3:17.0
0,6,3:17.0
1,6,3:17.0
2,6,3:17.0
3,6,3:17.0
3,5,3:17.0
4,5,3:17.0
4,4,3:17.0
4,3,3:17.0
4,2,3:17.0
4,1,3:17.0
4,0,3:17.0
4,-1,3:17.0
4,-2,3:17.0
4,-3,3:17.0
