[META]
version=2.0
spawnOnBlockType=12
spawnSunlight=True
spawnDarkness=False
spawnWater=True
spawnLava=False
underFill=True
randomRotation=True
dig=True
tree=True
branch=False
needsFoundation=True
rarity=80
collisionPercentage=30
spawnElevationMin=0
spawnElevationMax=128
groupId=Palm
groupFrequencyMin=1
groupFrequencyMax=5
groupSeperationMin=0
groupSeperationMax=5
branchLimit=6
spawnInBiome=All
[DATA]
0,0,0:85
0,0,1:85
0,0,2:85
0,0,3:85
0,0,4:85
0,0,5:85
0,0,6:17.0
-3,0,6:18.0
0,-3,6:18.0
0,3,6:18.0
3,0,6:18.0
0,0,7:18.0
-1,0,7:18.0
1,0,7:18.0
0,-1,7:18.0
0,1,7:18.0
0,-2,7:18.0
0,2,7:18.0
-2,0,7:18.0
2,0,7:18.0
-1,-1,7:18.0
1,1,7:18.0
-1,1,7:18.0
1,-1,7:18.0
0,-3,7:18.0
0,3,7:18.0
-3,0,7:18.0
3,0,7:18.0
-2,0,8:18.0
-1,0,8:18.0
0,-2,8:18.0
0,-1,8:18.0
0,1,8:18.0
0,2,8:18.0
1,0,8:18.0
2,0,8:18.0
